[2022-07-13 00:00:02,237] {taskinstance.py:1179} INFO - Dependencies all met for <TaskInstance: user_processing.create_table scheduled__2022-07-12T00:00:00+00:00 [queued]>
[2022-07-13 00:00:02,271] {taskinstance.py:1179} INFO - Dependencies all met for <TaskInstance: user_processing.create_table scheduled__2022-07-12T00:00:00+00:00 [queued]>
[2022-07-13 00:00:02,271] {taskinstance.py:1376} INFO - 
--------------------------------------------------------------------------------
[2022-07-13 00:00:02,272] {taskinstance.py:1377} INFO - Starting attempt 1 of 1
[2022-07-13 00:00:02,273] {taskinstance.py:1378} INFO - 
--------------------------------------------------------------------------------
[2022-07-13 00:00:02,323] {taskinstance.py:1397} INFO - Executing <Task(PostgresOperator): create_table> on 2022-07-12 00:00:00+00:00
[2022-07-13 00:00:02,336] {standard_task_runner.py:52} INFO - Started process 8555 to run task
[2022-07-13 00:00:02,347] {standard_task_runner.py:79} INFO - Running: ['***', 'tasks', 'run', 'user_processing', 'create_table', 'scheduled__2022-07-12T00:00:00+00:00', '--job-id', '7', '--raw', '--subdir', 'DAGS_FOLDER/user_processing.py', '--cfg-path', '/tmp/tmp6qyvbs9s', '--error-file', '/tmp/tmp8y1u60vm']
[2022-07-13 00:00:02,351] {standard_task_runner.py:80} INFO - Job 7: Subtask create_table
[2022-07-13 00:00:02,536] {task_command.py:371} INFO - Running <TaskInstance: user_processing.create_table scheduled__2022-07-12T00:00:00+00:00 [running]> on host b0c7b58a654d
[2022-07-13 00:00:02,696] {taskinstance.py:1591} INFO - Exporting the following env vars:
AIRFLOW_CTX_DAG_OWNER=***
AIRFLOW_CTX_DAG_ID=user_processing
AIRFLOW_CTX_TASK_ID=create_table
AIRFLOW_CTX_EXECUTION_DATE=2022-07-12T00:00:00+00:00
AIRFLOW_CTX_TRY_NUMBER=1
AIRFLOW_CTX_DAG_RUN_ID=scheduled__2022-07-12T00:00:00+00:00
[2022-07-13 00:00:02,715] {base.py:68} INFO - Using connection ID 'postgres' for task execution.
[2022-07-13 00:00:02,717] {taskinstance.py:1909} ERROR - Task failed with exception
Traceback (most recent call last):
  File "/home/airflow/.local/lib/python3.7/site-packages/airflow/providers/postgres/operators/postgres.py", line 92, in execute
    self.hook.run(self.sql, self.autocommit, parameters=self.parameters)
  File "/home/airflow/.local/lib/python3.7/site-packages/airflow/hooks/dbapi.py", line 204, in run
    with closing(self.get_conn()) as conn:
  File "/home/airflow/.local/lib/python3.7/site-packages/airflow/providers/postgres/hooks/postgres.py", line 113, in get_conn
    self.conn = psycopg2.connect(**conn_args)
  File "/home/airflow/.local/lib/python3.7/site-packages/psycopg2/__init__.py", line 122, in connect
    conn = _connect(dsn, connection_factory=connection_factory, **kwasync)
psycopg2.OperationalError: connection to server on socket "/var/run/postgresql/.s.PGSQL.5432" failed: No such file or directory
	Is the server running locally and accepting connections on that socket?

[2022-07-13 00:00:02,744] {taskinstance.py:1420} INFO - Marking task as FAILED. dag_id=user_processing, task_id=create_table, execution_date=20220712T000000, start_date=20220713T000002, end_date=20220713T000002
[2022-07-13 00:00:02,782] {standard_task_runner.py:97} ERROR - Failed to execute job 7 for task create_table (connection to server on socket "/var/run/postgresql/.s.PGSQL.5432" failed: No such file or directory
	Is the server running locally and accepting connections on that socket?
; 8555)
[2022-07-13 00:00:02,816] {local_task_job.py:156} INFO - Task exited with return code 1
[2022-07-13 00:00:02,916] {local_task_job.py:273} INFO - 0 downstream tasks scheduled from follow-on schedule check
